Workbook
Name _dFin: 42735
Name _soNumFisc: 3201201523617
Name _soSigle: "PYTHAGORE CONSULTAN"

Sheet Balance
A1: N° compte | B1: Libellés | C1: Débit | D1: Crédit | E1: Débit | F1: Crédit | G1: Débit | H1: Crédit
A2: 101200 | B2: Capital souscrit, appelé, non | C2: 0 | D2: 0 | E2: 193000000 | F2: 193000000 | G2: 0 | H2: 0
A3: 101300 | B3: Capital souscrit, appelé, vers | C3: 0 | D3: 100000000 | E3: 0 | F3: 1e+10 | G3: 0 | H3: 10100000000
A4: 129000 | B4: REPORT À NOUVEAU DÉBITEUR | C4: 2748292 | D4: 0 | E4: 20055904 | F4: 0 | G4: 22804196 | H4: 0
A5: 139000 | B5: RÉSULTAT NET : PERTE | C5: 20055904 | D5: 0 | E5: 0 | F5: 20055904 | G5: 0 | H5: 0
A6: 160000 | B6: EMPRUNTS ET DETTES ASSIMILÉES | C6: 0 | D6: 5125000000 | E6: 5125000000 | F6: 0 | G6: 0 | H6: 0
A7: 161100 | B7: Emprunts obligataires ordinair | C7: 0 | D7: 7500000000 | E7: 7500000000 | F7: 0 | G7: 0 | H7: 0
A8: 162010 | B8: EMPRUNT CORIS BANK | C8: 0 | D8: 0 | E8: 247062318 | F8: 500000000 | G8: 0 | H8: 252937682
A9: 162020 | B9: EMPRUNT VISTA | C9: 0 | D9: 0 | E9: 0 | F9: 15000000000 | G9: 0 | H9: 15000000000
A10: 162030 | B10: EMPRUNT WBI | C10: 0 | D10: 0 | E10: 539354385 | F10: 5e+09 | G10: 0 | H10: 4.4606456e+09
A11: 213100 | B11: LOGICIELS | C11: 0 | D11: 0 | E11: 64245912 | F11: 0 | G11: 64245912 | H11: 0
A12: 221800 | B12: AUTRES TERRAINS | C12: 0 | D12: 0 | E12: 962734139 | F12: 0 | G12: 962734139 | H12: 0
A13: 222800 | B13: TERRAINS RIVERAINS | C13: 3000000 | D13: 0 | E13: 437179000 | F13: 4400000 | G13: 435779000 | H13: 0
... A286: 779000 | B286: REPRISES DE CHARGES POUR DEPRE | C286: 0 | D286: 0 | E286: 0 | F286: 925930 | G286: 0 | H286: 925930
A287: Total bilan | C287: 0 | D287: 3.0517578e-07 | E287: 2.1757276e+11 | F287: 2.1704661e+11 | G287: 5.2614863e+08 | H287: 0
A288: Total gestion | C288: 0 | D288: 0 | E288: 3.0379781e+10 | F288: 30905929932 | G288: 0 | H288: 5.2614863e+08
A289: Total hors-bilan | C289: 0 | D289: 0 | E289: 0 | F289: 0 | G289: 0 | H289: 0
A290: TOTAL SOCIETE | C290: 0 | D290: 3.0517578e-07 | E290: 2.4795254e+11 | F290: 2.4795254e+11 | G290: 0 | H290: 0
D292: =SUM(D2:D291) | E292: =SUM(E2:E291)

Sheet COUVERTURE
F4: BURKINA FASO
C6: MINISTERE DE L'ECONOMIE DES FINANCES ET DU DEVELOPPEMENT
F8: DIRECTION GENERALE DES IMPOTS
E31: LIASSE SYSTEME NORMAL

Sheet GARDE
B2: BURKINA FASO
B3: MINISTERE DE L'ECONOMIE DES FINANCES ET DU DEVELOPPEMENT
B4: DIRECTION GENERALE DES IMPOTS
C8: DGE
C12: ETATS FINANCIERS NORMALISES SYSTEME COMPTABLE OHADA (SYSCOHADA)
E16: EXERCICE CLOS LE
E17: 45291
D20: DESIGNATION DE L'ENTITE
B22: DENOMINATION SOCIALE :
B23: (ou nom et prénoms de l'exploitant)
B26: SIGLE USUEL :
B28: ADRESSE COMPLETE : | C28: 01 BP 4928 OUAGADOUGOU 01
B30: N° IFU DU CONTRIBUABLE : | D30: 00124780J
B31: N° DE TELEDECLARANT (NES): | D31: 0
B32: SYSTEME NORMAL
B33: Documents déposés | H33: Réservé à la Direction Générale des Impôts
B35: Fiche d'identification et renseignements divers | F35: x | H35: Date de dépôt
B36: Bilan | F36: x
B37: Compte de résultat | F37: x
B38: Tableau des flux de trésorerie | F38: x
B39: Notes annexes | F39: x | H39: Nom de l'agent de la DGI ayant réceptionné le dépôt
B40: Etats supplémentaires DGI | F40: x
B44: Nombre de pages déposées par exemplaire : | F44: 58 | H44: Signature de l'agent et cachet du service
B45: Nombre d'exemplaires déposés : | F45: 3

Sheet RECEVABILITE
A1: - 0 -
A3: CONDITIONS DE RECEVABILITE
B5: Entités utilisant des imprimés:
B7: * N'utilisez que des imprimés normalisés
B9: * Remplir chaque page de façon parfaitement lisible sans décalage de lignes
B11: * Ne créer aucune rubrique
B13: * Eviter toute surcharge et donner les explications sur une feuille séparée
B15: * N'utilisez que des codes indiqués dans les tables
B17: * N'utilisez que des imprimés en noir et blanc
B20: Entités produisant les états financiers à l'aide de l'outil informatique
B22: * Reproduire à l'identique la contexture des imprimés normalisés
B24: * Fournir une liasse comprenant à la fois : la fiche d'identification et renseignements divers et les états financiers correspondant au système comptable
B26: * Ne créer aucune rubrique
B28: * N'utilisez que des codes indiqués dans les tables
... B37: Les Notes annexes non chiffrées doivent êtres supprimées. Cependant, elles devront être indiquées dans la Fiche récapitulative des Notes Annexes.

Sheet NOTE36 (TABLE DES CODES)
A1: - 0 -
H2: NOTE 36 SYSTEME NORMAL
A3: Dénomination sociale de l'entité : | C3: =GARDE!D22
A4: Adresse : | B4: =GARDE!C28 | H4: Sigle usuel: | I4: =GARDE!C26
A5: N° IFU du contribuable : | C5: =GARDE!D30 | E5: Exercice clos le : | G5: =GARDE!E17 | H5: Durée (en mois) : | I5: ='FICHE R1'!U5
A6: N° de télédéclarant (NES): | C6: =GARDE!D31
A7: NOTE 36 : TABLE DES CODES
A9: 1- Code forme juridique (1) | F9: 3- Code pays du siège social
A11: Société Anonyme (SA) à participation publique | D11: 0 | E11: 0
F12: Pays UEMOA (2)
A13: Société Anonyme (SA) | D13: 0 | E13: 1
F14: Pays CEMAC (3)
A15: Société par Actions Simplifiée (SAS) | D15: 0 | E15: 2
F16: Autres pays OHADA (4)
A17: Société à Responsabilité Limitée (SARL) | D17: 0 | E17: 3 | F17: Afrique du Sud | I17: 2 | J17: 0
F18: Autres pays africains | I18: 2 | J18: 1
A19: Société en Commandite Simple (SCS) | D19: 0 | E19: 4
F20: Suisse | I20: 2 | J20: 2
A21: Société en Nom Collectif (SNC) | D21: 0 | E21: 5
F22: France | I22: 2 | J22: 3
A23: Société en Participation (SP) | D23: 0 | E23: 6
F24: Autres pays de l'Union Européenne | I24: 3 | J24: 9
A25: Groupement d'Intérêt Economique (GIE) | D25: 0 | E25: 7
F26: U.S.A. | I26: 4 | J26: 0
A27: Association | D27: 0 | E27: 8
F28: Canada | I28: 4 | J28: 1
A29: Autre forme juridique (à préciser) | D29: 0 | E29: 9 | F29: Brésil | I29: 4 | J29: 3
F30: Autres pays américains | I30: 4 | J30: 9
A31: 2 - Code régime fiscal
F32: Chine | I32: 5 | J32: 0
A33: Réel normal | E33: 1 | F33: Inde | I33: 5 | J33: 2
F34: Liban | I34: 5 | J34: 3
A35: Réel simplifié | E35: 2 | F35: Autres pays asiatiques | I35: 5 | J35: 9
F36: Russie | I36: 6 | J36: 0
A37: CME | E37: 3
F38: Autres pays | I38: 9 | J38: 9
A39: AUTRE | E39: 4
F40: (Zone monétaire = Zone franc CFA)
A42: (1) Remplacer le premier 0 par 1 si l'entreprise bénéficie d'un agrément prioritaire
A43: (2) Bénin = 01 ; Burkina = 02 ; Côte d'Ivoire = 03 ; Guinée Bissau = 04 ; Mali = 05 ; Niger = 06 ; Sénégal = 07 ; Togo = 08
...

Sheet NOTE36 Suite (nomenclature)
A1: NOTE 36 (suite Nomenclature)
A2: Sélectionner la ou les codes activités selon le découpage de votre chiffre d'affaires pour le renseignement de la fiche R2
A6: CODES ACTIVITES ECONOMIQUES
A7: Agriculture vivrière | H7: Industries du caoutchouc et des plastiques
A8: 001 001 Culture céréalière | H8: 022 001 Fabrication du caoutchouc naturel
A9: 001 002 Culture de tubercules et plantains | H9: 022 002 Industries du caoutchouc
A10: 001 003 Culture de légumes | H10: 022 003 Fabrication de matières plastiques
A11: 001 004 Culture de condiments | H11: Fabrication d’autres produits minéraux non métalliques et de matériaux
A12: 001 005 Culture de fruits | H12: de construction
A13: 001 006 Culture d’autres produits de l’Agriculture vivrière | H13: 023 001 Industrie du verre
A14: Agriculture industrielle et d’exportation | H14: 023 002 Fabrication de produits minéraux pour la construction
A15: 002 001 Culture de canne à sucre | H15: 023 003 Fabrication d’autres produits minéraux non métalliques
A16: 002 002 Culture d’arachide d’huilerie | H16: Métallurgie et travail des métaux
A17: 002 003 Culture d’arachide de bouche | H17: 024 001 Métallurgie
A18: 002 004 Culture de tabac | H18: 024 002 Travail des métaux
... A56: 012 000 Industries laitières | H56: Postes, télécommunications

Sheet FICHE R1
A1: - 1 -
R2: FICHE R1
A3: Dénomination sociale de l'entité : | E3: =GARDE!D22
A4: Adresse : | P4: Sigle usuel : | S4: =GARDE!C26
A5: N° IFU du contribuable : | H5: Exercice clos le : | Q5: Durée (en mois) : | U5: 12
A6: N° de télédéclarant (NES) : | E6: =GARDE!D31
A7: FICHE R1 : FICHE D'IDENTIFICATION ET RENSEIGNEMENTS DIVERS 1
A8: ZA | C8: EXERCICE COMPTABLE : | M8: DU: | N8: 44927 | R8: AU: | S8: 45291
A10: ZB | C10: DATE D'ARRETE EFFECTIF DES COMPTES : | T10: ZD
A12: ZC | C12: EXERCICE PRECEDENT CLOS LE : | K12: DUREE EXERCICE PRECEDENT EN MOIS : | U12: 12
A14: ZE | J14: ZF
C15: Greffe | D15: N°Registre du Commerce | K15: N° Répertoire des entités
A17: ZG | E17: ZH | P17: ZI
C18: N° de caisse sociale | F18: N° Code Importateur | Q18: Code activité principale
A20: ZJ | C20: =+E3 | Q20: =+S4
C21: Désignation de l'entité | Q21: Sigle
A23: ZK | Q23: OUAGADOUGOU
E24: Adresse e-mail | K24: Code | N24: Boîte Postale | Q24: Ville
A26: ZL
C27: Adresse géographique complète (Immeuble, rue, quartier, ville, pays)
P28: ZN
A29: ZM
C30: Désignation précise de l'activité principale exercée par l'entité | P30: % Capacité production utile
A32: ZO
C33: Nom, adresse, téléphone, adresse e-mail et qualité de la personne à contacter en cas de demande
A35: ZP
C36: Nom, adresse, téléphone et e-mail du salarié de l'entité ou
C37: du professionnel comptable inscrit à l'Ordre des Experts-comptables ayant établi les états financiers
A39: ZQ
A43: ZR
C44: Nom, adresse, téléphone, e-mail et numéro d'inscription à l'Ordre des Experts-comptables
C45: de l'Expert comptablble ayant délivré l'attestation d'exécution de la mission du commissariat aux comptes
A47: ZS | O47: Non | T47: Oui
N48: Etats financiers approuvés par l'Assemblée Générale (cocher la case)
J49: ZW
A50: ZT | J50: Domiciliations bancaires
C51: Nom du signataire des états financiers | J51: Banque | Q51: Numéro de compte
A53: ZU
C54: Qualité du signataire des états financiers
A56: ZV
...

Sheet FICHE R2
A1: - 2 -
AG2: FICHE R2
A3: Dénomination sociale de l'entité :
A4: Adresse : | AC4: Sigle usuel :
A5: N° IFU du contribuable : | Q5: Exercice clos le : | AC5: Durée (en mois) : | AI5: ='FICHE R1'!U5
A6: N° de télédéclarant (NES) :
A7: FICHE R2 : FICHE D'IDENTIFICATION ET RENSEIGNEMENTS DIVERS 2
V8: Contrôle de l'Entité (cocher la case)
A9: ZX | D9: Forme juridique (1) : | Q9: 0 | R9: 1 | V9: ZZ5 | X9: Entité sous contrôle public
A11: ZY | D11: Régime fiscal (1) : | Q11: 1 | V11: ZZ6 | X11: Entité sous contrôle privé national | AK11: X
A13: ZZ1 | D13: Pays du siège social (1) : | Q13: 0 | R13: 2 | V13: ZZ7 | X13: Entité sous contrôle privé étranger
A15: ZZ2 | D15: Nombre d'établissements dans le pays : | Q15: 0 | R15: 1
A17: ZZ3 | D17: Nombre d'établissements hors du pays pour | Q17: 0 | R17: 0
D18: lesquels une comptabilité distincte est tenue :
A20: ZZ4 | D20: Première année d'exercice dans le pays : | Q20: 2 | R20: 0 | S20: 2 | T20: 1
A23: ACTIVITE DE L'ENTITE
A25: Désignation de l'activité (2) | P25: Code nomenclature d'activité (1) | Y25: Chiffre d'affaires HT (CA HT) ou Valeur ajoutée (VA) (3) (4) | AI25: % activité dans le CA HT ou la VA
A52: Divers (4)
P54: TOTAL | Z54: =Z29+Z32+Z35+Z38+Z41+Z44+Z47+Z50+Z52
A57: (1) Note 36 Suite (Nomenclature)
A58: (2) Lister de manière précise les activités dans l'ordre décroissant du C.A.HT ou de la valeur ajoutée (V.A).
A59: (3) Rayer la mention inutile - Au Burkina Faso, pour les besoins de l'INSD, on préfèrera le chiffre d'affaires.
A60: (4) Indiquer dans la note annexe n°21 "Chiffre d'affaires et autres produits", la liste détaillée des activités classées dans la rubrique "Divers"

Sheet FICHE R3
A1: - 3 -
I2: FICHE R3
A3: Dénomination sociale de l'entité : | C3: ='FICHE R1'!E3
A4: Adresse : | B4: ='FICHE R1'!D4 | H4: Sigle usuel : | J4: ='FICHE R1'!S4
A5: N° IFU du contribuable : | C5: ='FICHE R1'!E5 | E5: Exercice clos le : | F5: ='FICHE R1'!J5 | H5: Durée (en mois) : | J5: ='FICHE R1'!U5
A6: N° de télédéclarant (NES) : | C6: ='FICHE R1'!E6
A7: FICHE R3 : FICHE D'IDENTIFICATION ET RENSEIGNEMENTS DIVERS 3
A8: DIRIGEANTS (1)
A10: Nom et Prénoms | C10: Nationalité | D10: Autres nationalités (à préciser) (2) | E10: Qualité | F10: N° d'identification fiscale | H10: Adresse (BP, ville, pays, adresse géographique et adresse email)
A22: (1) Dirigeants = Président Directeur Général, Directeur Général, Administrateur Général, Gérant, Autres.
A23: (2) En cas de double nationalité
A24: MEMBRES DU CONSEIL D'ADMINISTRATION
A26: Nom et Prénoms | C26: Structure représentée | E26: Qualité | G26: Adresse (BP, ville, pays, adresse géographique et adresse email)

Sheet FICHE R4
I2: FICHE R4
A3: Dénomination sociale de l'entité : | C3: =GARDE!D22
A4: Adresse : | H4: Sigle usuel : | I4: =GARDE!C26
A5: N° IFU du contribuable : | E5: Exercice clos le : | H5: Durée (en mois) : | I5: =TFT!J5
A6: N° de télédéclarant (NES): | C6: =GARDE!D31
A7: FICHE R4 : FICHE RECAPITULATIVE DES NOTES ANNEXES PRESENTEES (1)
A8: NOTES | B8: INTITULES | I8: A | J8: N/A
A9: NOTE 1 | B9: DETTES GARANTIES PAR DES SURETES REELLES ET LES ENGAGEMENTS FINANCIERS
A10: NOTE 2 | B10: INFORMATIONS OBLIGATOIRES
A11: NOTE 3A | B11: IMMOBILISATIONS BRUTES
A12: NOTE 3B | B12: BIENS PRIS EN LOCATION-ACQUISITION
A13: NOTE 3C | B13: IMMOBILISATIONS : AMORTISSEMENTS
A14: NOTE 3C bis | B14: IMMOBILISATIONS : DEPRECIATIONS
A15: NOTE 3D | B15: IMMOBILISATIONS : PLUS-VALUES ET MOINS VALUE DE CESSION
A16: NOTE 3E | B16: INFORMATIONS SUR LES REEVALUATIONS EFFECTUEES PAR L'ENTITE
A17: NOTE 4 | B17: IMMOBILISATIONS FINANCIERES
A18: NOTE 5 | B18: ACTIF CIRCULANT ET DETTES CIRCULANTES HAO
A19: NOTE 6 | B19: STOCKS ET ENCOURS
A20: NOTE 7 | B20: CLIENTS
... A61: ETATS DGI | B61: ETATS SUPPLEMENTAIRES DGI
A63: (1) les Notes non documentées ne doivent pas être jointes aux états financiers. Leur contenu peut être amélioré par les entités Par ailleurs, dans une note, les lignes non chiffrées doivent être supprimées. Par exemple, dans la note 24 Services Extérieurs, lorsque la ligne sous-traitance générale n'est pas chiffrée, elle ne doit pas figurer dans les notes.
A64: (2) A : Applicable A/N : Non applicable.
A65: Par exemple pour une entité qui n'a pas de stocks et en-cours, elle doit cocher à l'intersection ('ligne NOTE 6' & 'colonne N/A')

Sheet BILAN
A1: - 4 -
L2: BILAN SYSTEME NORMAL PAGE 1/1
A3: Dénomination sociale de l'entité : | C3: =+GARDE!D22
A4: Adresse : | C4: =+GARDE!C28 | L4: Sigle usuel : | N4: =GARDE!C26
A5: N° IFU du contribuable : | C5: =GARDE!D30 | I5: Exercice clos le : | K5: =GARDE!E17 | L5: Durée (en mois) : | N5: 12
A6: N° de télédéclarant (NES): | C6: =GARDE!D31
A7: BILAN
A8: REF | B8: ACTIF | E8: NOTE | F8: EXERCICE au 31/12/ N | I8: EXERCICE AU 31/12/N-1 | J8: REF | K8: PASSIF | L8: NOTE | M8: EXERCICE AU 31/12/N | N8: EXERCICE AU 31/12/N-1
F10: BRUT | G10: AMORT et DEPREC. | H10: NET | I10: NET | M10: NET | N10: NET
A11: AD | B11: IMMOBILISATIONS INCORPORELLES | E11: 3 | F11: =CtaCptSolde("20*","21*") | G11: =-CtaCptSolde("280*","281*")-CtaCptSolde("290*","291*") | H11: =[A_AD.EtLoc]=CtaCptSolde("20*","21*")+CtaCptSolde("280*","281*")+CtaCptSolde("290*","291*") | I11: =[A_AD_N1.EtLoc]=CtaCptSoldeNm1("20*","21*")+CtaCptSoldeNm1("280*","281*")+CtaCptSoldeNm1("290*","291*") | J11: CA | K11: Capital | L11: 13 | M11: =[P_CA.EtLoc]=CtaCptSoldeCrédit("10*") | N11: =[P_CA_N1.EtLoc]=CtaCptSoldeCréditNm1("10*")
A12: AE | B12: Frais de développement et de prospection | F12: =CtaCptSolde("20*") | G12: =-CtaCptSolde("280*")-CtaCptSolde("290*") | H12: =CtaCptSolde("20*")+CtaCptSolde("280*")+CtaCptSolde("290*") | I12: =CtaCptSoldeNm1("20*")+CtaCptSoldeNm1("280*")+CtaCptSoldeNm1("290*") | J12: CB | K12: Apporteurs capital non appelé (-) | L12: 13
A13: AF | B13: Brevets, licences, logiciels et droits similaires | F13: =CtaCptSolde("21*") | G13: =-CtaCptSolde("281*")-CtaCptSolde("291*") | H13: =CtaCptSolde("21*")+CtaCptSolde("281*")+CtaCptSolde("291*") | I13: =CtaCptSoldeNm1("21*")+CtaCptSoldeNm1("281*")+CtaCptSoldeNm1("291*") | J13: CD | K13: Primes liées au capital social | L13: 14
A14: AG | B14: Fonds commercial et droit au bail | J14: CE | K14: Ecarts de réévaluation | L14: 3e
A15: AH | B15: Autres immobilisations incorporelles | J15: CF | K15: Réserves indisponibles | L15: 14
A16: AI | B16: IMMOBILISATIONS CORPORELLES | E16: 3 | F16: =CtaCptSolde("22*","245*") | G16: =-CtaCptSolde("282*","2849*")-CtaCptSolde("292*","2949*") | H16: =[A_AI.EtLoc]=CtaCptSolde("22*","245*")+CtaCptSolde("282*","2849*")+CtaCptSolde("292*","2949*") | I16: =[A_AI_N1.EtLoc]=CtaCptSoldeNm1("22*","245*")+CtaCptSoldeNm1("282*","2849*")+CtaCptSoldeNm1("292*","2949*") | J16: CG | K16: Réserves libres | L16: 14 | M16: =[P_CG.EtLoc]=CtaCptSoldeCrédit("11*") | N16: =[P_CG_N1.EtLoc]=CtaCptSoldeCréditNm1("11*")
A17: AJ | B17: Terrains (1) dont Placement Net : | F17: =CtaCptSolde("22*") | G17: =-CtaCptSolde("282*")-CtaCptSolde("292*") | H17: =CtaCptSolde("22*")+CtaCptSolde("282*")+CtaCptSolde("292*") | I17: =CtaCptSoldeNm1("22*")+CtaCptSoldeNm1("282*")+CtaCptSoldeNm1("292*") | J17: CH | K17: Report à nouveau (+ ou -) | L17: 14 | M17: =[P_CH.EtLoc]=-CtaCptSolde("12*") | N17: =[P_CH_N1.EtLoc]=-CtaCptSoldeNm1("12*")
A18: AK | B18: Bâtiments(1) dont Placement Net : | F18: =CtaCptSolde("231*","233*") | G18: =-CtaCptSolde("2831*","2833*")-CtaCptSolde("2931*","2933*") | H18: =CtaCptSolde("231*","233*")+CtaCptSolde("2831*","2833*")+CtaCptSolde("2931*","2933*") | I18: =CtaCptSoldeNm1("231*","233*")+CtaCptSoldeNm1("2831*","2833*")+CtaCptSoldeNm1("2931*","2933*") | J18: CJ | K18: Résultat net de l'exercice (bénéfice + ou perte -) | M18: =[P_CJ.EtLoc]=-CtaCptSolde("7*")-CtaCptSolde("6*") | N18: =[P_CJ_N1.EtLoc]=-CtaCptSoldeNm1("7*")-CtaCptSoldeNm1("6*")
A19: AL | B19: Aménagements, agencements et installations | F19: =CtaCptSolde("234*","239*") | G19: =-CtaCptSolde("2834*","2839*")-CtaCptSolde("2934*","2939*") | H19: =CtaCptSolde("234*","239*")+CtaCptSolde("2834*","2839*")+CtaCptSolde("2934*","2939*") | I19: =CtaCptSoldeNm1("234*","239*")+CtaCptSoldeNm1("2834*","2839*")+CtaCptSoldeNm1("2934*","2939*") | J19: CL | K19: Subventions d'investissement | L19: 15 | M19: =[P_CL.EtLoc]=CtaCptSoldeCrédit("14*") | N19: =[P_CL_N1.EtLoc]=CtaCptSoldeCréditNm1("14*")
A20: AM | B20: Matériel, mobilier et actifs biologiques | F20: =CtaCptSolde("240*","244*") | G20: =-CtaCptSolde("2840*","2844*")-CtaCptSolde("2940*","2944*") | H20: =CtaCptSolde("240*","244*")+CtaCptSolde("2840*","2844*")+CtaCptSolde("2940*","2944*") | I20: =CtaCptSoldeNm1("240*","244*")+CtaCptSoldeNm1("2840*","2844*")+CtaCptSoldeNm1("2940*","2944*") | J20: CM | K20: Provisions réglementées | L20: 15 | M20: =[P_CM.EtLoc]=CtaCptSoldeCrédit("15*") | N20: =[P_CM_N1.EtLoc]=CtaCptSoldeCréditNm1("15*")
A21: AN | B21: Matériel de transport | F21: =CtaCptSolde("245*") | G21: =-CtaCptSolde("2845*","2849*")-CtaCptSolde("2945*","2949*") | H21: =CtaCptSolde("245*")+CtaCptSolde("2845*","2849*")+CtaCptSolde("2945*","2949*") | I21: =CtaCptSoldeNm1("245*")+CtaCptSoldeNm1("2845*","2849*")+CtaCptSoldeNm1("2945*","2949*") | J21: CP | K21: TOTAL CAPITAUX PROPRES ET RESSOURCES ASSIMILEES | M21: =[P_CP.EtLoc]=[P_CA.EtLoc]+[P_CG.EtLoc]+[P_CH.EtLoc]+[P_CJ.EtLoc]+[P_CL.EtLoc]+[P_CM.EtLoc] | N21: =[P_CP_N1.EtLoc]=[P_CA_N1.EtLoc]+[P_CG_N1.EtLoc]+[P_CH_N1.EtLoc]+[P_CJ_N1.EtLoc]+[P_CL_N1.EtLoc]+[P_CM_N1.EtLoc]
A22: AP | B22: AVANCES ET ACOMPTES VERSES SUR IMMOBILISATIONS | E22: 3 | F22: =CtaCptSolde("25*") | G22: =-CtaCptSolde("2850*","2859*")-CtaCptSolde("2950*","2959*") | H22: =[A_AP.EtLoc]=CtaCptSolde("25*")+CtaCptSolde("2850*","2859*")+CtaCptSolde("2950*","2959*") | I22: =[A_AP_N1.EtLoc]=CtaCptSoldeNm1("25*")+CtaCptSoldeNm1("2850*","2859*")+CtaCptSoldeNm1("2950*","2959*") | J22: DA | K22: Emprunts et dettes financières diverses | L22: 16 | M22: =[P_DA.EtLoc]=CtaCptSoldeCrédit("16*","17*") | N22: =[P_DA_N1.EtLoc]=CtaCptSoldeCréditNm1("16*","17*")
A23: AQ | B23: IMMOBILISATIONS FINANCIERES | E23: 4 | F23: =CtaCptSolde("26*","27*") | G23: =-CtaCptSolde("2860*","2869*")-CtaCptSolde("2960*","2969*") | H23: =[A_AQ.EtLoc]=CtaCptSolde("26*","27*")+CtaCptSolde("2860*","2869*")+CtaCptSolde("2960*","2969*") | I23: =[A_AQ_N1.EtLoc]=CtaCptSoldeNm1("26*","27*")+CtaCptSoldeNm1("2860*","2869*")+CtaCptSoldeNm1("2960*","2969*") | J23: DB | K23: Dettes de location-acquisition | L23: 16
A24: AR | B24: Titres de participation | F24: =CtaCptSolde("26*") | G24: =-CtaCptSolde("2860*","2865*")-CtaCptSolde("2960*","2965*") | H24: =CtaCptSolde("26*")+CtaCptSolde("2860*","2865*")+CtaCptSolde("2960*","2965*") | I24: =CtaCptSoldeNm1("26*")+CtaCptSoldeNm1("2860*","2865*")+CtaCptSoldeNm1("2960*","2965*") | J24: DC | K24: Provisions pour risques et charges | L24: 16 | M24: =[P_DC.EtLoc]=CtaCptSolde("19*") | N24: =[P_DC_N1.EtLoc]=CtaCptSoldeNm1("19*")
A25: AS | B25: Autres immobilisations financières | F25: =CtaCptSolde("27*") | G25: =-CtaCptSolde("2866*","2869*")-CtaCptSolde("2966*","2969*") | H25: =CtaCptSolde("27*")+CtaCptSolde("2866*","2869*")+CtaCptSolde("2966*","2969*") | I25: =CtaCptSoldeNm1("27*")+CtaCptSoldeNm1("2866*","2869*")+CtaCptSoldeNm1("2966*","2969*") | J25: DD | K25: TOTAL DETTES FINANCIERES ET RESSOURCES ASSIMILEES | M25: =[P_DD.EtLoc]=[P_DA.EtLoc]+[P_DC.EtLoc] | N25: =[P_DD_N1.EtLoc]=[P_DA_N1.EtLoc]+[P_DC_N1.EtLoc]
A26: AZ | B26: TOTAL ACTIF IMMOBILISE | F26: =CtaCptSolde("20*","27*") | G26: =-CtaCptSolde("280*","2869*")-CtaCptSolde("290*","2969*") | H26: =[A_AZ.EtLoc]=[A_AD.EtLoc]+[A_AI.EtLoc]+[A_AP.EtLoc]+[A_AQ.EtLoc] | I26: =[A_AZ_N1.EtLoc]=[A_AD_N1.EtLoc]+[A_AI_N1.EtLoc]+[A_AP_N1.EtLoc]+[A_AQ_N1.EtLoc] | J26: DF | K26: TOTAL RESSOURCES STABLES | M26: =[P_DF.EtLoc]=[P_CP.EtLoc]+[P_DD.EtLoc] | N26: =[P_DF_N1.EtLoc]=[P_CP_N1.EtLoc]+[P_DD_N1.EtLoc]
A27: BA | B27: ACTIF CIRCULANT HAO | E27: 5 | F27: =CtaCptSoldeDébit("47*","49*") | H27: =[A_BA.EtLoc]=CtaCptSoldeDébit("47*","49*") | I27: =[A_BA_N1.EtLoc]=CtaCptSoldeDébitNm1("47*","49*") | J27: DH | K27: Dettes circulantes HAO | L27: 5 | M27: =[P_DH.EtLoc]=CtaCptSoldeCrédit("47*","49*") | N27: =[P_DH_N1.EtLoc]=CtaCptSoldeCréditNm1("47*","49*")
A28: BB | B28: STOCKS ET ENCOURS | E28: 6 | F28: =CtaCptSoldeDébit("3*","39*")-CtaCptSoldeCrédit("3*","39*") | H28: =[A_BB.EtLoc]=CtaCptSoldeDébit("3*","39*")-CtaCptSoldeCrédit("3*","39*") | I28: =[A_BB_N1.EtLoc]=CtaCptSoldeDébitNm1("3*","39*")-CtaCptSoldeCréditNm1("3*","39*") | J28: DI | K28: Clients, avances reçues | L28: 7 | M28: =[P_DI.EtLoc]=CtaCptSoldeCrédit("41*") | N28: =[P_DI_N1.EtLoc]=CtaCptSoldeCréditNm1("41*")
A29: BG | B29: CREANCES ET EMPLOIS ASSIMILES | F29: =CtaCptSoldeDébit("40*","46*") | H29: =[A_BH.EtLoc]+[A_BI.EtLoc]+[A_BJ.EtLoc] | I29: =[A_BH_N1.EtLoc]+[A_BI_N1.EtLoc]+[A_BJ_N1.EtLoc] | J29: DJ | K29: Fournisseurs d'exploitation | L29: 17 | M29: =[P_DJ.EtLoc]=CtaCptSoldeCrédit("40*") | N29: =[P_DJ_N1.EtLoc]=CtaCptSoldeCréditNm1("40*")
A30: BH | B30: Fournisseurs avances versées | E30: 17 | F30: =CtaCptSoldeDébit("40*") | H30: =[A_BH.EtLoc]=CtaCptSoldeDébit("40*") | I30: =[A_BH_N1.EtLoc]=CtaCptSoldeDébitNm1("40*") | J30: DK | K30: Dettes fiscales et sociales | L30: 18 | M30: =[P_DK.EtLoc]=CtaCptSoldeCrédit("42*","45*") | N30: =[P_DK_N1.EtLoc]=CtaCptSoldeCréditNm1("42*","45*")
A31: BI | B31: Clients | E31: 7 | F31: =CtaCptSoldeDébit("41*") | H31: =[A_BI.EtLoc]=CtaCptSoldeDébit("41*") | I31: =[A_BI_N1.EtLoc]=CtaCptSoldeDébitNm1("41*") | J31: DM | K31: Autres dettes | L31: 19 | M31: =[P_DM.EtLoc]=CtaCptSoldeCrédit("46*") | N31: =[P_DM_N1.EtLoc]=CtaCptSoldeCréditNm1("46*")
A32: BJ | B32: Autres créances | E32: 8 | F32: =CtaCptSoldeDébit("42*","46*") | H32: =[A_BJ.EtLoc]=CtaCptSoldeDébit("42*","46*") | I32: =[A_BJ_N1.EtLoc]=CtaCptSoldeDébitNm1("42*","46*") | J32: DN | K32: Provisions pour risques et charges à court terme | L32: 19
A33: BK | B33: TOTAL ACTIF CIRCULANT | F33: =CtaCptSoldeDébit("3*","46*") | H33: =[A_BK.EtLoc]=[A_BA.EtLoc]+[A_BB.EtLoc]+[A_BH.EtLoc]+[A_BI.EtLoc]+[A_BJ.EtLoc] | I33: =[A_BK_N1.EtLoc]=[A_BA_N1.EtLoc]+[A_BB_N1.EtLoc]+[A_BH_N1.EtLoc]+[A_BI_N1.EtLoc]+[A_BJ_N1.EtLoc] | J33: DP | K33: TOTAL PASSIF CIRCULANT | M33: =[P_DP.EtLoc]=[P_DH.EtLoc]+[P_DI.EtLoc]+[P_DJ.EtLoc]+[P_DK.EtLoc]+[P_DM.EtLoc] | N33: =[P_DP_N1.EtLoc]=[P_DH_N1.EtLoc]+[P_DI_N1.EtLoc]+[P_DJ_N1.EtLoc]+[P_DK_N1.EtLoc]+[P_DM_N1.EtLoc]
A34: BQ | B34: Titres de placement | E34: 9 | F34: =CtaCptSoldeDébit("50*") | H34: =[A_BQ.EtLoc]=CtaCptSoldeDébit("50*") | I34: =[A_BQ_N1.EtLoc]=CtaCptSoldeDébitNm1("50*")
A35: BR | B35: Valeurs à encaisser | E35: 10 | F35: =CtaCptSoldeDébit("51*") | H35: =[A_BR.EtLoc]=CtaCptSoldeDébit("51*") | I35: =[A_BR_N1.EtLoc]=CtaCptSoldeDébitNm1("51*") | J35: DQ | K35: Banques, crédits d'escompte | L35: 20 | M35: =[P_DQ.EtLoc]=CtaCptSoldeCrédit("50*","56*") | N35: =[P_DQ_N1.EtLoc]=CtaCptSoldeCréditNm1("50*","56*")
A36: BS | B36: Banques, chèques postaux, caisse et assimilés | E36: 11 | F36: =CtaCptSoldeDébit("52*","59*") | H36: =[A_BS.EtLoc]=CtaCptSoldeDébit("52*","59*") | I36: =[A_BS_N1.EtLoc]=CtaCptSoldeDébitNm1("52*","59*") | J36: DR | K36: Banques, établissements financiers et crédits de trésorerie | L36: 20 | M36: =[P_DR.EtLoc]=CtaCptSoldeCrédit("57*","59*") | N36: =[P_DR_N1.EtLoc]=CtaCptSoldeCréditNm1("57*","59*")
A37: BT | B37: TOTAL TRESORERIE-ACTIF | F37: =CtaCptSoldeDébit("50*","59*") | H37: =[A_BT.EtLoc]=[A_BQ.EtLoc]+[A_BR.EtLoc]+[A_BS.EtLoc] | I37: =[A_BT_N1.EtLoc]=[A_BQ_N1.EtLoc]+[A_BR_N1.EtLoc]+[A_BS_N1.EtLoc] | J37: DT | K37: TOTAL TRESORERIE-PASSIF | M37: =[P_DT.EtLoc]=[P_DQ.EtLoc]+[P_DR.EtLoc] | N37: =[P_DT_N1.EtLoc]=[P_DQ_N1.EtLoc]+[P_DR_N1.EtLoc]
A38: BU | B38: Ecart de conversion-Actif | E38: 12 | J38: DV | K38: Ecart de conversion-Passif | L38: 12
A39: BZ | B39: TOTAL GENERAL | F39: =CtaCptSoldeDébit("20*","59*") | H39: =[A_BZ.EtLoc]=[A_AZ.EtLoc]+[A_BK.EtLoc]+[A_BT.EtLoc] | I39: =[A_BZ_N1.EtLoc]=[A_AZ_N1.EtLoc]+[A_BK_N1.EtLoc]+[A_BT_N1.EtLoc] | J39: DZ | K39: TOTAL GENERAL | M39: =[P_DZ.EtLoc]=[P_DF.EtLoc]+[P_DP.EtLoc]+[P_DT.EtLoc] | N39: =[P_DZ_N1.EtLoc]=[P_DF_N1.EtLoc]+[P_DP_N1.EtLoc]+[P_DT_N1.EtLoc]

Sheet RESULTAT
A1: - 5 -
H2: COMPTE DE RESULTAT SYSTEME NORMAL PAGE 1/1
A3: Dénomination sociale de l'entité : | C3: =BILAN!C3
A4: Adresse : | C4: =BILAN!C4 | I4: Sigle usuel : | J4: =BILAN!N4
A5: N° IFU du contribuable : | C5: =BILAN!C5 | E5: Exercice clos le : | F5: =BILAN!K5 | I5: Durée (en mois) : | J5: =BILAN!N5
A6: N° de télédéclarant (NES): | C6: ='FICHE R1'!E6
A7: COMPTE DE RESULTAT
A8: REF | B8: LIBELLES | G8: (1) | H8: NOTE | I8: EXERCICE AU 31/12/N | J8: EXERCICE AU 31/12/N-1
I10: NET | J10: NET
A11: TA | B11: Ventes de marchandises | F11: A | G11: + | H11: 21 | I11: =[011.EtLoc]=-CtaCptSolde("70*","701*") | J11: =[011N1.EtLoc]=-CtaCptSoldeNm1("70*","701*")
A12: RA | B12: Achats de marchandises | G12: - | H12: 22 | I12: =[021.EtLoc]=CtaCptSolde("601*") | J12: =[021N1.EtLoc]=CtaCptSoldeNm1("601*")
A13: RB | B13: Variation de stocks de marchandises | G13: -/+ | H13: 6 | I13: =[022.EtLoc]=CtaCptSolde("6031*") | J13: =[022N1.EtLoc]=CtaCptSoldeNm1("6031*")
A14: XA | B14: MARGE COMMERCIALE (Somme TA à RB) | I14: =[031.EtLoc]=[011.EtLoc]-[021.EtLoc]-[022.EtLoc] | J14: =[031N1.EtLoc]=[011N1.EtLoc]-[021N1.EtLoc]-[022N1.EtLoc]
A15: TB | B15: Ventes de produits fabriqués | F15: B | G15: + | H15: 21 | I15: =[041.EtLoc]=-CtaCptSolde("702*","704*") | J15: =[041N1.EtLoc]=-CtaCptSoldeNm1("702*","704*")
A16: TC | B16: Travaux, services vendus | F16: C | G16: + | H16: 21 | I16: =[051.EtLoc]=-CtaCptSolde("705*","706*") | J16: =[051N1.EtLoc]=-CtaCptSoldeNm1("705*","706*")
A17: TD | B17: Produits accessoires | F17: D | G17: + | H17: 21 | I17: =[061.EtLoc]=-CtaCptSolde("707*") | J17: =[061N1.EtLoc]=-CtaCptSoldeNm1("707*")
A18: XB | B18: CHIFFRE D'AFFAIRES (A + B + C + D) | I18: =[071.EtLoc]=[041.EtLoc]+[051.EtLoc]+[061.EtLoc]+[011.EtLoc] | J18: =[071N1.EtLoc]=[041N1.EtLoc]+[051N1.EtLoc]+[061N1.EtLoc]+[011N1.EtLoc]
A19: TE | B19: Production stockée (ou déstockage) | G19: -/+ | H19: 6 | I19: =[062.EtLoc]=-CtaCptSolde("713*") | J19: =[062N1.EtLoc]=-CtaCptSoldeNm1("713*")
A20: TF | B20: Production immobilisée | H20: 21 | I20: =[052.EtLoc]=-CtaCptSolde("72*","73*") | J20: =[052N1.EtLoc]=-CtaCptSoldeNm1("72*","73*")
A21: TG | B21: Subventions d’exploitation | H21: 21 | I21: =[072.EtLoc]=-CtaCptSolde("71*") | J21: =[072N1.EtLoc]=-CtaCptSoldeNm1("71*")
A22: TH | B22: Autres produits | G22: + | H22: 21 | I22: =[082.EtLoc]=-CtaCptSolde("74*","76*") | J22: =[082N1.EtLoc]=-CtaCptSoldeNm1("74*","76*")
A23: TI | B23: Transferts de charges d'exploitation | G23: + | H23: 12 | I23: =[092.EtLoc]=-CtaCptSolde("781*") | J23: =[092N1.EtLoc]=-CtaCptSoldeNm1("781*")
A24: RC | B24: Achats de matières premières et fournitures liées | G24: - | H24: 22 | I24: =[101.EtLoc]=-CtaCptSolde("601*","602*") | J24: =[101N1.EtLoc]=-CtaCptSoldeNm1("601*","602*")
A25: RD | B25: Variation de stocks de matières premières et fournitures liées | G25: -/+ | H25: 6 | I25: =[102.EtLoc]=-CtaCptSolde("6032*") | J25: =[102N1.EtLoc]=-CtaCptSoldeNm1("6032*")
A26: RE | B26: Autres achats | G26: - | H26: 22 | I26: =[201.EtLoc]=-CtaCptSolde("604*","609*") | J26: =[201N1.EtLoc]=-CtaCptSoldeNm1("604*","609*")
A27: RF | B27: Variation de stocks d’autres approvisionnements | G27: -/+ | H27: 6 | I27: =[202.EtLoc]=-CtaCptSolde("6033*","6038*") | J27: =[202N1.EtLoc]=-CtaCptSoldeNm1("6033*","6038*")
A28: RG | B28: Transports | G28: - | H28: 23 | I28: =[301.EtLoc]=-CtaCptSolde("61*") | J28: =[301N1.EtLoc]=-CtaCptSoldeNm1("61*")
A29: RH | B29: Services extérieurs | G29: - | H29: 24 | I29: =[302.EtLoc]=-CtaCptSolde("62*","63*") | J29: =[302N1.EtLoc]=-CtaCptSoldeNm1("62*","63*")
A30: RI | B30: Impôts et taxes | G30: - | H30: 25 | I30: =[401.EtLoc]=-CtaCptSolde("64*") | J30: =[401N1.EtLoc]=-CtaCptSoldeNm1("64*")
A31: RJ | B31: Autres charges | G31: - | H31: 26 | I31: =[402.EtLoc]=-CtaCptSolde("65*") | J31: =[402N1.EtLoc]=-CtaCptSoldeNm1("65*")
A32: XC | B32: VALEUR AJOUTEE (XB +RA+RB) + (somme TE à RJ) | I32: =[091.EtLoc]=[071.EtLoc]+[062.EtLoc]+[052.EtLoc]+[072.EtLoc]+[082.EtLoc]+[092.EtLoc]+[101.EtLoc]+[102.EtLoc]+[201.EtLoc]+[202.EtLoc]+[301.EtLoc]+[302.EtLoc]+[401.EtLoc]+[402.EtLoc] | J32: =[091N1.EtLoc]=[071N1.EtLoc]+[062N1.EtLoc]+[052N1.EtLoc]+[072N1.EtLoc]+[082N1.EtLoc]+[092N1.EtLoc]+[101N1.EtLoc]+[102N1.EtLoc]+[201N1.EtLoc]+[202N1.EtLoc]+[301N1.EtLoc]+[302N1.EtLoc]+[401N1.EtLoc]+[402N1.EtLoc]
A33: RK | B33: Charges de personnel | G33: - | H33: 27 | I33: =[121.EtLoc]=CtaCptSolde("66*") | J33: =[121N1.EtLoc]=CtaCptSoldeNm1("66*")
A34: XD | B34: EXCEDENT BRUT D'EXPLOITATION (XC+RK) | I34: =[131.EtLoc]=[091.EtLoc]-([121.EtLoc]) | J34: =[131N1.EtLoc]=[091N1.EtLoc]-([121N1.EtLoc])
A35: TJ | B35: Reprises d’amortissements, provisions et dépréciations | G35: + | H35: 28 | I35: =[141.EtLoc]=-CtaCptSolde("78*") | J35: =[141N1.EtLoc]=-CtaCptSoldeNm1("78*")
A36: RL | B36: Dotations aux amortissements, aux provisions et dépréciations | G36: - | H36: 3C&28 | I36: =[171.EtLoc]=CtaCptSolde("68*") | J36: =[171N1.EtLoc]=CtaCptSoldeNm1("68*")
A37: XE | B37: RESULTAT D'EXPLOITATION (XD+TJ+ RL) | I37: =[191.EtLoc]=[131.EtLoc]+[141.EtLoc]-[171.EtLoc] | J37: =[191N1.EtLoc]=[131N1.EtLoc]+[141N1.EtLoc]-[171N1.EtLoc]
A38: TK | B38: Revenus financiers et assimilés | G38: + | H38: 29 | I38: =[211.EtLoc]=-CtaCptSolde("77*") | J38: =[211N1.EtLoc]=-CtaCptSoldeNm1("77*")
A39: TL | B39: Reprises de provisions et dépréciations financières | G39: + | H39: 28 | I39: =[212.EtLoc]=-CtaCptSolde("797*") | J39: =[212N1.EtLoc]=-CtaCptSoldeNm1("797*")
A40: TM | B40: Transferts de charges financières | G40: + | H40: 12 | I40: =[221.EtLoc]=-CtaCptSolde("787*") | J40: =[221N1.EtLoc]=-CtaCptSoldeNm1("787*")
A41: RM | B41: Frais financiers et charges assimilées | G41: - | H41: 29 | I41: =[231.EtLoc]=CtaCptSolde("67*") | J41: =[231N1.EtLoc]=CtaCptSoldeNm1("67*")
...

Sheet TFT
A1: - 6 -
H2: FLUX DE TRESORERIE SYSTEME NORMAL PAGE 1/1
A3: Dénomination sociale de l'entité : | C3: =BILAN!C3
A4: Adresse : | C4: =BILAN!C4 | I4: Sigle usuel : | J4: =BILAN!N4
A5: N° IFU du contribuable : | C5: =BILAN!C5 | E5: Exercice clos le : | F5: =BILAN!K5 | I5: Durée (en mois) : | J5: =BILAN!N5
A6: N° de télédéclarant (NES): | C6: =GARDE!D31
A7: TABLEAU DES FLUX DE TRESORERIE
A8: REF | B8: LIBELLES | H8: NOTE | I8: EXERCICE | J8: EXERCICE
I9: N | J9: N-1
A10: ZA | B10: Trésorerie nette au 1er janvier (Trésorerie actif N-1 - Trésorerie passif N-1) | G10: A | I10: =[ZZA.EtLoc]=CtaCptSoldeNm1("50*","58*") | J10: 2945092497
B11: Flux de trésorerie provenant des activités opérationnelles
A12: FA | B12: Capacité d'Autofinancement Globale (CAFG) | I12: =[ZFA.EtLoc]=[T_CAFG.EtLoc]
A13: FB | B13: - Variation d'actif circulant HAO (1) | I13: =[ZFB.EtLoc]=-CtaCptSoldeDébit("46*","49*")+CtaCptSoldeDébitNm1("46*","49*")
A14: FC | B14: - Variation des stocks | I14: =[ZFC.EtLoc]=-CtaCptSoldeDébit("3*")+CtaCptSoldeDébitNm1("3*")
A15: FD | B15: - Variation des créances | I15: =[ZFD.EtLoc]=-CtaCptSoldeDébit("4*","45*")+CtaCptSoldeDébitNm1("4*","45*")
A16: FE | B16: + Variation du passif circulant (1) | I16: =[ZFE.EtLoc]=CtaCptSoldeCrédit("40*")+CtaCptSoldeCrédit("41*")+CtaCptSoldeCrédit("42*")+CtaCptSoldeCrédit("43*")+CtaCptSoldeCrédit("44*")+CtaCptSoldeCrédit("45*","49*")-CtaCptSoldeCréditNm1("40*")-CtaCptSoldeCréditNm1("41*")-CtaCptSoldeCréditNm1("42*")-CtaCptSoldeCréditNm1("43*")-CtaCptSoldeCréditNm1("44*")-CtaCptSoldeCréditNm1("45*","49*")
B17: Variation du BF lié aux activités opérationnelles
B18: FB+FC+FD+FE : | C18: =I13+I14+I15+I16 | E18: =IFERROR(J13+J14+J15+J16,"")
A19: ZB | B19: Flux de trésorerie provenant des activités opérationnelles (Somme FA à FE) | G19: B | I19: =[ZZB.EtLoc]=[ZFA.EtLoc]+[ZFB.EtLoc]+[ZFC.EtLoc]+[ZFD.EtLoc]+[ZFE.EtLoc]
B20: Flux de trésorerie provenant des activités d’investissements
A21: FF | B21: - Décaissements liés aux acquisitions d'immobilisations incorporelles | I21: =[ZFF.EtLoc]=-CtaCptSolde("21*")+CtaCptSoldeNm1("21*")
A22: FG | B22: - Décaissements liés aux acquisitions d'immobilisations corporelles | I22: =[ZFG.EtLoc]=-CtaCptSolde("22*","25*")+CtaCptSoldeNm1("22*","25*")
A23: FH | B23: - Décaissements liés aux acquisitions d'immobilisations financières | I23: =[ZFH.EtLoc]=-CtaCptSolde("26*","27*")+CtaCptSoldeNm1("26*","27*")
A24: FI | B24: + Encaissements liés aux cessions d’immobilisations incorporelles et corporelles
A25: FJ | B25: + Encaissements liés aux cessions d’immobilisations financières
A26: ZC | B26: Flux de trésorerie provenant des activités d’investissement (somme FF à FJ) | G26: C | I26: =[ZZC.EtLoc]=[ZFF.EtLoc]+[ZFG.EtLoc]+[ZFH.EtLoc]
B27: Flux de trésorerie provenant du financement par les capitaux propres
A28: FK | B28: + Augmentations de capital par apports nouveaux | I28: =[ZFK.EtLoc]=-CtaCptSolde("10*")+CtaCptSoldeNm1("10*")
A29: FL | B29: + Subventions d'investissement reçues | I29: =[ZFL.EtLoc]=-CtaCptSolde("14*")+CtaCptSoldeNm1("14*")
A30: FM | B30: - Prélèvements sur le capital
A31: FN | B31: - Dividendes versés
A32: ZD | B32: Flux de trésorerie provenant des capitaux propres (somme FK à FN) | G32: D | I32: =[ZZD.EtLoc]=[ZFK.EtLoc]+[ZFL.EtLoc]
B33: Trésorerie provenant du financement par les capitaux étrangers
A34: FO | B34: + Emprunts | I34: =[ZFO.EtLoc]=-CtaCptSolde("16*")+CtaCptSoldeNm1("16*")
A35: FP | B35: + Autres dettes financières diverses
A36: FQ | B36: - Remboursements des emprunts et autres dettes financières
A37: ZE | B37: Flux de trésorerie provenant des capitaux étrangers (somme FO à FQ) | G37: E | I37: =[ZZE.EtLoc]=[ZFO.EtLoc]
A38: ZF | B38: Flux de trésorerie provenant des activités de financement (D+E) | G38: F | I38: =[ZZF.EtLoc]=[ZZD.EtLoc]+[ZZE.EtLoc]
A39: ZG | B39: VARIATION DE LA TRÉSORERIE NETTE DE LA PÉRIODE (B+C+F) | G39: G | I39: =[ZZG.EtLoc]=[ZZB.EtLoc]+[ZZC.EtLoc]+[ZZF.EtLoc]
A40: ZH | B40: Trésorerie nette au 31 Décembre (G+A) | G40: H | I40: =[ZZH.EtLoc]=[ZZG.EtLoc]+[ZZA.EtLoc]
...

Sheet TAB BORD
A1: TABLEAU DE BORD DE CONTRÔLE DES FLUX DE TRESORERIE
C3: MONTANT
C4: EXERCICE N | D4: EXERCICE N-1
A5: Trésorerie actif de N-1 | B5: + | C5: =BILAN!I37
A6: Compte 472 versements restant à effectuer sur titres de placement non libérés de l'année N-1 | B6: - / +
A7: Trésorerie passif de N-1 | B7: - | C7: =-BILAN!N37
A8: Trésorerie au 1 er janvier (A) | C8: =+C5-C7 | D8: =SUM(D5:D7)
C11: MONTANT
C12: EXERCICE N | D12: EXERCICE N-1
A13: Excédent brut d'exploitation (poste XD compte de résultat) | B13: + | C13: =RESULTAT!I34
A14: Compte 654 solde débiteur balance N | B14: +
A15: Compte 754 solde créditeur balance N | B15: -
A16: Résultat financier (poste XF compte de résultat) | B16: + | C16: =-RESULTAT!I43
A17: Autres produits HAO (poste TO compte de résultat) | B17: + | C17: =+RESULTAT!I46
A18: Autres charges HAO (poste RP compte de résultat) | B18: - | C18: =-RESULTAT!I48
A19: Participation des trvailleurs (poste RQ du compte résultat) | B19: - | C19: =+RESULTAT!I50
A20: Impôts sur le résultat (poste RS du compte de résultat) | B20: - | C20: =+RESULTAT!I51
A21: Capacité d'Autfinancement Globale (CAFG) | C21: =SUM(C13:C20) | D21: =SUM(D13:D20)
A22: Actif circulant HAO (poste BA des bilans) | B22: + | C22: =BILAN!H27-BILAN!I27
A23: Compte 485 (exclure) | B23: -
A24: Montant affecté au poste FB du TFT | C24: =SUM(C22:C23) | D24: =SUM(D22:D23)
A25: Variation des stocks (poste BB des bilans) poste FC du TFT | B25: - / + | C25: =BILAN!H28-BILAN!I28
A26: Variation des créances et emplois assimilé (poste BG des bilans) | B26: - / + | C26: =BILAN!H29-BILAN!I29
A27: Variation du compte 478 | B27: - / +
A28: Variation du compte 419 | B28: - / +
A29: Variation du compte 414 | B29: - / +
A30: Variation du compte 467 | B30: - / +
A31: Variation du compte 458 | B31: - / +
A32: Variation du compte 4494 | B32: - / +
A33: Variation du compte 4751 | B33: - / +
A34: Montant affecté au poste FD du TFT | C34: =SUM(C25:C33) | D34: =SUM(D25:D33)
A35: Variation du passif circulant (poste DP des bilans) | B35: - / + | C35: =BILAN!M33-BILAN!N33
A36: Variation du compte 409 | B36: - / + | C36: =BILAN!H30-BILAN!I30
A37: Variation du compte 404 | B37: - / +
A38: Variation du compte 481 | B38: - / + | C38: =BILAN!M27-BILAN!N27
A39: Variation du compte 482 | B39: - / +
A40: Variation du compte 467 | B40: - / +
A41: Variation du compte 4752 | B41: - / +
A42: Variation du compte 472 | B42: - / +
A43: Montant affecté au poste FE du TFT | C43: =SUM(C35:C42) | D43: =SUM(D35:D42)
...

Sheet NOTE 1
A1: - 8 -
H2: NOTE 1 SYSTEME NORMAL
A3: Dénomination sociale de l'entité : | C3: ='FICHE R4'!C3
A4: Adresse : | B4: ='FICHE R4'!B4 | H4: Sigle usuel : | I4: ='FICHE R4'!I4
A5: N° IFU du contribuable : | C5: ='FICHE R4'!C5 | F5: Exercice clos le : | H5: Durée (en mois) : | I5: ='FICHE R4'!I5
A6: N° de télédéclarant (NES): | C6: ='FICHE R4'!C6
A7: NOTE 1: DETTES GARANTIES PAR DES SURETES REELLES ET LES ENGAGEMENTS FINANCIERS
A8: LIBELLES | E8: Note | F8: Montant brut (1) | G8: SURETES REELLES (2)
G9: Hypothèques | H9: Nantissements | I9: Gages/autres
A10: Emprunts et dettes financières diverses : | E10: 16
A11: Emprunts obligataires convertibles
A12: Autres emprunts obligataires
A13: Emprunts et dettes des établissements de crédit | F13: =+BILAN!M22
A14: Autres dettes financières
A15: SOUS TOTAL (1) | F15: =SUM(F11:F14)
A16: Dettes de location-acquisition : | E16: 16
A17: Dettes de crédit-bail immobilier
A18: Dettes de crédit-bail mobilier
A19: Dettes sur contrats de location-vente
A20: Autres dettes sur contrats de location-acquisition
A21: SOUS TOTAL (2) | F21: =SUM(F17:F20)
A22: Dettes du passif circulant :
A23: Fournisseurs et comptes rattachés | E23: 17
A24: Clients | E24: 7
A25: Personnel | E25: 18
A26: Sécurité sociale et organismes sociaux | E26: 18
A27: Etat | E27: 18
A28: Organismes internationaux | E28: 19
A29: Associés et groupe | E29: 19
A30: Créditeurs divers | E30: 19
A31: SOUS TOTAL (3)
A32: TOTAL (1) + (2) + (3)
A33: ENGAGEMENTS FINANCIERS | G33: Engagements réciproques | H33: Engagements donnés | I33: Engagements reçus
A34: Engagements consentis à des entités liées
A35: Primes de remboursement des obligations non échues
A36: Avals, cautions, garanties
A37: Hypothèques, nantissements, gages, autres
A38: Effets escomptés non échus
A39: Créances commerciales et professionnelles cédées
A40: Abandons de créances conditionnels
...

Sheet NOTE 2
A1: - 0 -
H2: NOTE 2 SYSTEME NORMAL
A3: Dénomination sociale de l'entité : | C3: ='NOTE 1'!C3
A4: Adresse : | B4: ='NOTE 1'!B4 | H4: Sigle usuel : | I4: ='NOTE 1'!I4
A5: N° IFU du contribuable : | C5: ='NOTE 1'!C5 | F5: Exercice clos le : | H5: Durée (en mois) : | I5: ='NOTE 1'!I5
A6: N° de télédéclarant (NES): | C6: ='NOTE 1'!C6
A7: NOTE 2: INFORMATIONS OBLIGATOIRES
A8: A - DECLARATION DE CONFORMITE AU SYSCOHADA ET FAITS MARQUANTS DE L'EXERCICE
A9: Les états financiers sont établis conformément au système comptable OHADA et à l'acte uniforme relatif au droit comptable et à l'information financière.
A10: B - REGLES ET METHODES COMPTABLES
A11: Les postultas, les conventions et règles d'évaluation édictées par le SYSCOHADA et l'acte uniforme ont été respectés dans l'élaboration des états financiers.
A12: C- DEROGATION AUX POSTULATS ET CONVENTIONS COMPTABLES
A13: Les postultas et conventions ont été tous respectés sans aucune dérogation.
A14: D - INFORMATIONS COMPLEMENTAIRES RELATIVES AU BILAN, AU COMPTE DE RESULTAT ET AU TABLEAU DES FLUX DE TRESORERIE
A15: Il n'y a pas d'informations complémentaires relatives aux autres états financiers.
A17: Commentaire :
A18: ● Mentionner les faits marquants après la déclaration de conformité.
A19: Seuls les éléments ayant une incidence comptable significative ou qui misent à la comparabilité des exercices doivent être mentionnés. Par exemple, le lancement d'un produit sur le marché, ou la perte du principal client de l'entité.
A20: ● Décrire les régles et méthodes utilisées pour l'établissement des états financiers et celles utilisées dans le cas de contrat pluri- exercices, de contrats de concession, de l'établissement de comptes intermédiaires, de fusion et opérations assimilées comme indiquées dans les opérations et problèmes spécifiques.

Sheet NOTE 3A
A1: - 9 -
I2: NOTE 3A SYSTEME NORMAL
A3: Dénomination sociale de l'entité : | C3: ='NOTE 1'!C3
A4: Adresse : | B4: ='NOTE 1'!B4 | I4: Sigle usuel : | J4: ='NOTE 1'!I4
A5: N° IFU : | C5: ='NOTE 1'!C5 | F5: Exercice clos le : | G5: ='NOTE 1'!G5 | I5: Durée (en mois) : | J5: ='NOTE 1'!I5
A6: N° de télédéclarant (NES): | C6: ='NOTE 1'!C6
A7: NOTE 3A : IMMOBILISATIONS (BRUTES)
A8: SITUATIONS ET MOUVEMENTS | D8: A | E8: AUGMENTATIONS B | H8: DIMINUTIONS C | J8: D = A + B - C
D9: MONTANT BRUT A L'OUVERTURE DE L'EXERCICE | E9: Acquisitions Apports Créations | F9: Virements de poste à poste | G9: Suite à une réévaluation pratiquée au cours de l'exercice | H9: Cessions Scissions Hors service | I9: Virements de poste à poste | J9: MONTANT BRUT A LA CLOTURE DE L'EXERCICE
A10: RUBRIQUES
A11: IMMOBILISATIONS INCORPORELLES | D11: =SUM(D12:D15) | E11: =SUM(E12:E15) | F11: =SUM(F12:F15) | G11: =SUM(G12:G15) | H11: =SUM(H12:H15) | I11: =SUM(I12:I15) | J11: =D11+E11+F11+G11-H11-I11
A12: Frais de développement et de prospection | J12: =D12+E12+F12+G12-H12-I12
A13: Brevets, licences, logiciels, et droits similaires | E13: =+BILAN!F13 | J13: =D13+E13+F13+G13-H13-I13
A14: Fonds commercial et droit au bail | J14: =D14+E14+F14+G14-H14-I14
A15: Autres immobilisations incorporelles | J15: =D15+E15+F15+G15-H15-I15
A16: IMMOBILISATIONS CORPORELLES
A17: Terrains hors immeuble de placement
A18: Terrains - immeuble de placement
A19: Bâtiments hors immeuble de placement
A20: Bâtiments - immeuble de placement
A21: Aménagements, agencements et installations
A22: Matériel, mobilier et actifs biologiques
A23: Matériel de transport
A24: AVANCES ET ACOMPTES VERSES SUR IMMOBILISATIONS
A25: Avances et acomptes sur immobilisations incorporelles
A26: Avances et acomptes sur immobilisations corporelles
A27: IMMOBILISATIONS FINANCIERES
... A31: Commentaire :
A32: ● Toute variation significative doit être commentée. | E32: ● Indiquer les créances du groupe avec nature et date d'échéance.
A33: ● Détailler les éléments constitutifs du fonds commercial et indiquer la date d'acquisition. | E33: ● Pour les banques, DAT indiquer le nom de la banque le montant et la date d'échéance.
A34: ● Pour l'immobilisation incorporelle relative à la concession faire un descriptif de l'accord. | E34: ● Pour les frais de développement, donner toutes les informations mentionnées dans la partie Opérations et problèmes spécifiques.
A35: ● Indiquer : | E35: ● Donner le détail des produits et charges liés aux immeubles de placement.
A36: - la nature de la créance ;
A37: - la durée de la concession ;
A38: - l'échéance.

Sheet NOTE 3B
A1: - 0 -
K2: NOTE 3B SYSTEME NORMAL
A3: Dénomination sociale de l'entité : | C3: ='NOTE 1'!C3
A4: Adresse : | B4: ='NOTE 1'!B4 | K4: Sigle usuel : | L4: ='NOTE 1'!I4
A5: N° IFU : | C5: ='NOTE 1'!C5 | H5: Exercice clos le : | I5: ='NOTE 1'!G5 | K5: Durée (en mois) : | L5: ='NOTE 1'!I5
A6: N° de télédéclarant (NES): | C6: ='NOTE 1'!C6
A7: NOTE 3B : BIENS PRIS EN LOCATION ACQUISITION
A8: SITUATIONS ET MOUVEMENTS | F8: A | G8: AUGMENTATIONS B | J8: DIMINUTIONS C | L8: D = A + B - C
E9: NATURE DU CONTRAT (I ; M ; A) [1] | F9: MONTANT BRUT A L'OUVERTURE DE L'EXERCICE | G9: Acquisitions Apports Créations | H9: Virements de poste à poste | I9: Suite à une réévaluation pratiquée au cours de l'exercice | J9: Cessions Scissions Hors service | K9: Virements de poste à poste | L9: MONTANT BRUT A LA CLOTURE DE L'EXERCICE
A10: RUBRIQUES
A11: Terrains | L11: =F11+G11+H11+I11-J11-K11
A12: Bâtiments | L12: =F12+G12+H12+I12-J12-K12
A13: Matériel, mobilier | L13: =F13+G13+H13+I13-J13-K13
A14: Matériel de transport | L14: =F14+G14+H14+I14-J14-K14
A15: TOTAL IMMOBILISATIONS EN LOCATION-ACQUISITION | F15: =SUM(F11:F14) | G15: =SUM(G11:G14) | H15: =SUM(H11:H14) | I15: =SUM(I11:I14) | J15: =SUM(J11:J14) | K15: =SUM(K11:K14) | L15: =SUM(L11:L14)
A16: [1] I : Crédit-bail immobilier ; M : Crédit-bail mobilier ; A : Autres contrats (dédoubler le poste si montants
A17: Commentaire:
A18: ● Indiquer la nature du bien, le nom du bailleur et la durée du bail.

Sheet NOTE 3C
A1: - 10 -
N2: NOTE 3C SYSTEME NORMAL
A3: Dénomination sociale de l'entité : | C3: ='NOTE 1'!C3
A4: Adresse : | B4: ='NOTE 1'!B4 | L4: Sigle usuel : | N4: ='NOTE 1'!I4
A5: N° IFU : | C5: ='NOTE 1'!C5 | H5: Exercice clos le : | J5: ='NOTE 1'!G5 | L5: Durée (en mois) : | N5: ='NOTE 1'!I5
A6: N° de télédéclarant (NES): | C6: ='NOTE 1'!C6
A7: NOTE 3C : IMMOBILISATIONS (AMORTISSEMENTS)
A8: SITUATIONS ET MOUVEMENTS | D8: A | F8: B | H8: C | L8: D | N8: E = A + B - C - D
D9: AMORTISSEMENTS CUMULES A L'OUVERTURE DE L'EXERCICE | F9: AUGMENTATIONS: | H9: DIMINUTIONS : | L9: Virements de poste à poste | N9: CUMUL DES AMORTISSEMENTS A LA CLOTURE DE L'EXERCICE
A10: RUBRIQUES | F10: DOTATIONS DE L'EXERCICE | H10: Amortissements relatifs aux éléments sortis de l'actif | J10: Reprises d'amortissements
A11: Frais de développement et de prospection | N11: =D11+F11-H11-J11-L11
A12: Brevets, licences, logiciels et droits similaires | F12: =+BILAN!G13 | N12: =D12+F12-H12-J12-L12
A13: Fonds commercial et droit au bail | N13: =D13+F13-H13-J13-L13
A14: Autres immobilisations incorporelles | N14: =D14+F14-H14-J14-L14
A15: IMMOBILISATIONS INCORPORELLES
A16: Terrains hors immeuble de placement
A17: Terrains - immeuble de placement
A18: Bâtiments hors immeuble de placement
A19: Bâtiments - immeuble de placement
A20: Aménagements, agencements et installations
A21: Matériel, mobilier et actifs biologiques
A22: Matériel de transport
A23: IMMOBILISATIONS CORPORELLES
A24: TOTAL GENERAL
A25: Commentaire :
A26: ● Indiquer
... A28: - la durée d'utilité ou les taux d'amortissements utilisés.

Sheet NOTE 3C BIS
A1: - 0 -
J2: NOTE 3C BIS SYSTEME NORMAL
A3: Dénomination sociale de l'entité : | C3: ='NOTE 1'!C3
A4: Adresse : | B4: ='NOTE 1'!B4 | J4: Sigle usuel : | K4: ='NOTE 1'!I4
A5: N° IFU : | C5: ='NOTE 1'!C5 | E5: Exercice clos le : | J5: Durée (mois) : | K5: ='NOTE 1'!I5
A6: N° de télédéclarant (NES): | C6: ='NOTE 1'!C6
A7: NOTE 3C BIS : IMMOBILISATIONS (DEPRECIATIONS)
A8: SITUATIONS ET MOUVEMENTS | D8: A | F8: B | H8: C | J8: D = A + B - C
D9: DEPRECIATIONS CUMULES A L'OUVERTURE DE L'EXERCICE | F9: AUGMENTATIONS: DOTATIONS DE L'EXERCICE | H9: DIMINUTIONS : REPRISES DE L'EXERCICE | J9: CUMUL DES DEPRECIATIONS A LA CLOTURE DE L'EXERCICE
A10: RUBRIQUES
A11: Frais de développement et de prospection | J11: =D11+F11-H11
A12: Brevets, licences, logiciels et droits similaires | J12: =D12+F12-H12
A13: Fonds commercial et droit au bail | J13: =D13+F13-H13
A14: Autres immobilisations incorporelles | J14: =D14+F14-H14
A15: IMMOBILISATIONS INCORPORELLES | D15: =SUM(D11:E14) | F15: =SUM(F11:G14) | H15: =SUM(H11:I14) | J15: =SUM(J11:K14)
A16: Terrains hors immeuble de placement | J16: =D16+F16-H16
A17: Terrains - immeuble de placement | J17: =D17+F17-H17
A18: Bâtiments hors immeuble de placement | J18: =D18+F18-H18
A19: Bâtiments - immeuble de placement | J19: =D19+F19-H19
A20: Aménagements, agencements et installations | J20: =D20+F20-H20
A21: Matériel, mobilier et actifs biologiques | J21: =D21+F21-H21
A22: Matériel de transport | J22: =D22+F22-H22
A23: IMMOBILISATIONS CORPORELLES | D23: =SUM(D16:E22) | F23: =SUM(F16:G22) | H23: =SUM(H16:I22) | J23: =SUM(J16:K22)
A24: TOTAL GENERAL | D24: =D15+D23 | F24: =F15+F23 | H24: =H15+H23 | J24: =J15+J23
A25: Commentaire :
A26: ● Indiquer les événements et circonstances qui ont conduit à la dépréciation et à la reprise.

Sheet NOTE 3D
A1: - 0 -
G2: NOTE 3D SYSTEME NORMAL
A3: Dénomination sociale de l'entité : | C3: ='NOTE 1'!C3
A4: Adresse : | B4: ='NOTE 1'!B4 | G4: Sigle usuel : | H4: ='NOTE 1'!I4
A5: N° IFU : | C5: ='NOTE 1'!C5 | D5: Exercice clos le : | G5: Durée (en mois) : | H5: ='NOTE 1'!I5
A6: N° de télédéclarant (NES): | C6: ='NOTE 1'!C6
A7: NOTE 3D : IMMOBILISATIONS (PLUS-VALUES ET MOINS- VALUES DE CESSION)
A8: SITUATIONS ET MOUVEMENTS | D8: MONTANT BRUT | E8: AMORTISSEMENTS PRATIQUES | F8: VALEUR COMPTABLE NETTE | G8: PRIX DE CESSION | H8: PLUS-VALUE OU MOINS-VALUE
A9: RUBRIQUES | D9: A | E9: B | F9: C = A - B | G9: D | H9: E = D - C
A10: Frais de développement et de prospection | F10: =D10-E10 | H10: =G10-F10
A11: Brevets, licences, logiciels et droits similaires | F11: =D11-E11 | H11: =G11-F11
A12: Fonds commercial et droit au bail | F12: =D12-E12 | H12: =G12-F12
A13: Autres immobilisations incorporelles | F13: =D13-E13 | H13: =G13-F13
A14: IMMOBILISATIONS INCORPORELLES | D14: =SUM(D10:D13) | E14: =SUM(E10:E13) | F14: =SUM(F10:F13) | G14: =SUM(G10:G13) | H14: =SUM(H10:H13)
A15: Terrains | F15: =D15-E15 | H15: =G15-F15
A16: Bâtiments | F16: =D16-E16 | H16: =G16-F16
A17: Aménagements, agencements et installations | F17: =D17-E17 | H17: =G17-F17
A18: Matériel, mobilier et actifs biologiques | F18: =D18-E18 | H18: =G18-F18
A19: Matériel de transport | F19: =D19-E19 | H19: =G19-F19
A20: IMMOBILISATIONS CORPORELLES | D20: =SUM(D15:D19) | E20: =SUM(E15:E19) | F20: =SUM(F15:F19) | G20: =SUM(G15:G19) | H20: =SUM(H15:H19)
A21: Titres de participations | F21: =D21-E21 | H21: =G21-F21
A22: Autres immobilisations financières | F22: =D22-E22 | H22: =G22-F22
A23: IMMOBILISATIONS FINANCIERES | D23: =SUM(D21:D22) | E23: =SUM(E21:E22) | F23: =SUM(F21:F22) | G23: =SUM(G21:G22) | H23: =SUM(H21:H22)
A24: TOTAL GENERAL | D24: =D14+D20+D23 | E24: =E14+E20+E23 | F24: =F14+F20+F23 | G24: =G14+G20+G23 | H24: =H14+H20+H23
A25: Commentaire :
A26: ● Mentionner la justification de la cession ainsi que la date d'acquisition et la date de sortie.

Sheet NOTE 3E
A1: - 0 -
H2: NOTE 3E SYSTEME NORMAL
A3: Dénomination sociale de l'entité : | C3: ='NOTE 1'!C3
A4: Adresse : | B4: ='NOTE 1'!B4 | H4: Sigle usuel : | I4: ='NOTE 1'!I4
A5: N° IFU : | C5: ='NOTE 1'!C5 | D5: Exercice clos le : | H5: Durée (en mois) : | I5: ='NOTE 1'!I5
A6: N° de télédéclarant (NES): | C6: ='NOTE 1'!C6
A7: NOTE 3E : INFORMATIONS SUR LES REEVALUATIONS EFFECTUEES PAR L'ENTITE
A8: Nature et date des réévaluations :
A10: Eléments réévalués par postes du bilan | F10: Montants en coûts historiques | G10: Montant réévalués | H10: Ecarts de réévaluation | I10: Amortissements supplémentaires
A18: TOTAL GENERAL | F18: =SUM(F11:F17) | G18: =SUM(G11:G17) | H18: =SUM(H11:H17) | I18: =SUM(I11:I17)
A19: Méthode de réévaluation utilisée :
A21: Traitement fiscal de l'écart de réévaluation et des amortissements supplémentaires :
A23: Montant de l'écart incorporé au capital :

Sheet NOTE 4
A1: - 0 -
J2: NOTE 4 SYSTEME NORMAL
A3: Dénomination sociale de l'entité : | C3: ='NOTE 1'!C3
A4: Adresse : | B4: ='NOTE 1'!B4 | I4: Sigle usuel : | J4: ='NOTE 1'!I4
A5: N° IFU : | C5: ='NOTE 1'!C5 | F5: Exercice clos le : | G5: ='NOTE 1'!G5 | I5: Durée (en mois) : | J5: ='NOTE 1'!I5
A6: N° de télédéclarant (NES): | C6: ='NOTE 1'!C6
A7: NOTE 4 : IMMOBILISATIONS FINANCIERES
A8: Libellés | F8: Année N | G8: Année N-1 | H8: Variation en % | I8: Créances à un an au plus | J8: Créances à plus d'un an et à deux ans au plus | K8: Créances à plus de deux ans
A9: Titres de participation | H9: =IF(G9,(F9-G9)/ABS(G9),IF(ISBLANK(G9),"",IF(F9,IF( F9 > 0,1,-1),"")))
A10: Prêts et créances | H10: =IF(G10,(F10-G10)/ABS(G10),IF(ISBLANK(G10),"",IF(F10,IF( F10 > 0,1,-1),"")))
A11: Prêt au personnel | H11: =IF(G11,(F11-G11)/ABS(G11),IF(ISBLANK(G11),"",IF(F11,IF( F11 > 0,1,-1),"")))
A12: Créances sur l'état | H12: =IF(G12,(F12-G12)/ABS(G12),IF(ISBLANK(G12),"",IF(F12,IF( F12 > 0,1,-1),"")))
A13: Titres immobilisés | H13: =IF(G13,(F13-G13)/ABS(G13),IF(ISBLANK(G13),"",IF(F13,IF( F13 > 0,1,-1),"")))
A14: Dépôts et cautionnements
A15: Intérêts courus
A16: Créances rattachées à des avances et participations à des GIE
A17: Immobilisations financières diverses
A18: TOTAL BRUT
A19: Dépréciations des titres de participation | H19: =IF(G19,(F19-G19)/ABS(G19),IF(ISBLANK(G19),"",IF(F19,IF( F19 > 0,1,-1),"")))
A20: Dépréciations des autres immobilisations financières | H20: =IF(G20,(F20-G20)/ABS(G20),IF(ISBLANK(G20),"",IF(F20,IF( F20 > 0,1,-1),"")))
A21: TOTAL NET DE DEPRECIATION | F21: =F18+F19+F20 | G21: =G18+G19+G20 | H21: =IF(G21,(F21-G21)/G21,IF(ISBLANK(G21),"",IF(F21,1,"")))
A23: Liste des filiales et participations :
A24: Dénomination sociale | E24: Localisation (ville / pays) | G24: Valeur d'acquisition | H24: % Détenu | I24: Montant des capitaux propres filiale | J24: Résultat dernier exercice filiale (1) | K24: Part de bénéfice reçue de la filiale (2)
A31: (1): Préciser s'il s'agit du résultat de l'exercice N ou du résultat de l'exercice N-1 | E31: (2): S'il s'agit du résultat de l'exercice n-1, renseigner la colonne "part du bénéfice reçue de la filiale"
A32: Commentaire :
A33: ● Justifier toute variation significative. | F33: ● Indiquer le nombre et la date d'acquisition des actions ou parts propres.
A34: ● Commenter toutes les créances anciennes. | F34: ● Dépréciation : indiquer les évènements et les circonstances qui ont motivé la dépréciation ou la reprise.
A35: ● Pour les créances relatives à la concession, faire un descriptif de l'accord.
A36: ● Indiquer :
A37: - la nature de la créance ;
A38: - la durée de la concession ;
A39: - l'échéance.

Sheet NOTE 5
A1: - 0 -
H2: NOTE 5 SYSTEME NORMAL
A3: Dénomination sociale de l'entité : | C3: ='NOTE 1'!C3
A4: Adresse : | B4: ='NOTE 1'!B4 | H4: Sigle usuel : | I4: ='NOTE 1'!I4
A5: N° IFU : | C5: ='NOTE 1'!C5 | E5: Exercice clos le : | F5: ='NOTE 1'!G5 | H5: Durée (en mois) : | I5: ='NOTE 1'!I5
A6: N° de télédéclarant (NES): | C6: ='NOTE 1'!C6
A7: NOTE 5 : ACTIF CIRCULANT ET DETTES CIRCULANTES HAO
A8: ACTIF CIRCULANT HAO
A9: Libellés | E9: Année N | G9: Année N-1 | I9: Variation en %
A10: Créances sur cessions d'immobilisations | I10: =IF(G10,(E10-G10)/G10,IF(ISBLANK(G10),"",IF(E10,IF( E10 > 0,1,-1),"")))
A11: Autres créances hors activités ordinaires | E11: =+BILAN!F27 | G11: 0 | I11: =IF(G11,(E11-G11)/G11,IF(ISBLANK(G11),"",IF(E11,IF( E11 > 0,1,-1),"")))
A12: TOTAL BRUT | E12: =SUM(E10:F11) | G12: =SUM(G10:H11) | I12: =IF(G12,(E12-G12)/G12,IF(ISBLANK(G12),"",IF(E12,IF( E12 > 0,1,-1),"")))
A13: Dépréciations des créances HAO | I13: =IF(G13,(E13-G13)/G13,IF(ISBLANK(G13),"",IF(E13,IF( E13 > 0,1,-1),"")))
A14: TOTAL NET DE DEPRECIATIONS | E14: =E12+E13 | G14: =G12+G13 | I14: =IF(G14,(E14-G14)/G14,IF(ISBLANK(G14),"",IF(E14,IF( E14 > 0,1,-1),"")))
A15: Commentaire:
A16: • Commenter toute variation significative.
A17: • Dépréciation : indiquer les évènements et les circonstances qui ont motivé la dépréciation ou la reprise.
A19: DETTES CIRCULANTES HAO
A21: Libellés | E21: Année N | G21: Année N-1 | I21: Variation en %
A22: Fournisseurs d'investissements | E22: =+BILAN!M27
A23: Fournisseurs d'investissements effets à payer
A24: Versements restant à effectuer sur titres de participation et titres immobilisés non libérés | I24: =IF(G24,(E24-G24)/G24,IF(ISBLANK(G24),"",IF(E24,IF( E24 > 0,1,-1),"")))
A25: Autres dettes hors activités ordinaires | I25: =IF(G25,(E25-G25)/G25,IF(ISBLANK(G25),"",IF(E25,IF( E25 > 0,1,-1),"")))
A26: TOTAL | E26: =SUM(E22:F25) | G26: =SUM(G22:H25) | I26: =IF(G26,(E26-G26)/G26,IF(ISBLANK(G26),"",IF(E26,IF( E26 > 0,1,-1),"")))
A27: Commentaire:
A28: ● Indiquer la date de cession et la nature de l'immobilisation achetée et/ou cédée.
A29: ● Expliciter toute variation significative.

Sheet NOTE 6
A1: - 0 -
I2: NOTE 6 SYSTEME NORMAL
A3: Dénomination sociale de l'entité : | C3: ='NOTE 1'!C3
A4: Adresse : | B4: ='NOTE 1'!B4 | I4: Sigle usuel : | J4: ='NOTE 1'!I4
A5: N° IFU : | C5: ='NOTE 1'!C5 | E5: Exercice clos le : | F5: ='NOTE 1'!G5 | I5: Durée (en mois) : | J5: ='NOTE 1'!I5
A6: N° de télédéclarant (NES): | C6: ='NOTE 1'!C6
A7: NOTE 6 : STOCKS ET EN COURS (1)
A8: Libellés | E8: Année N | G8: Année N-1 | I8: Variation de stock en valeur absolue | J8: Variation en %
A9: Marchandises | I9: =ABS(E9-G9) | J9: =IF(G9,(E9-G9)/G9,IF(ISBLANK(G9),"",IF(E9,IF( E9 > 0,1,-1),"")))
A10: Matières premières et fournitures liées
A11: Autres approvisionnements
A12: Produits en cours
A13: Services en cours
A14: Produits finis
A15: Produits intermédiaires
A16: Stocks en cours de route, en consignation ou en dépôt
A17: TOTAL BRUT STOCKS ET EN COURS | E17: =SUM(E9:F16) | G17: =SUM(G9:H16) | I17: =ABS(E17-G17) | J17: =IF(G17,(E17-G17)/G17,IF(ISBLANK(G17),"",IF(E17,IF( E17 > 0,1,-1),"")))
A18: Dépréciations des stocks | I18: =ABS(E18-G18) | J18: =IF(G18,(E18-G18)/G18,IF(ISBLANK(G18),"",IF(E18,IF( E18 > 0,1,-1),"")))
A19: TOTAL NET DE DEPRECIATIONS | E19: =E17+E18 | G19: =G17+G18 | I19: =ABS(E19-G19) | J19: =IF(G19,(E19-G19)/G19,IF(ISBLANK(G19),"",IF(E19,IF( E19 > 0,1,-1),"")))
A20: (1) Les stocks H.A.O. seront inscrits dans l'actif circulant H.A.O. que lorsque leur montant total est significatif (supérieur à 5 % du total de l'actif circulant).
A21: Commentaire :
A22: ● Indiquer la date de prise d'inventaire et décrire brièvement la procédure, les méthodes comptables adoptées pour évaluer le stock.
A23: ● Commenter toute variation significative des stocks.
A24: ● Indiquer le détail des stocks dépréciés et les évènements et circonstances qui ont conduit à la dépréciation et à la reprise.

Sheet NOTE 7
A1: - 0 -
I2: NOTE 7 SYSTEME NORMAL
A3: Dénomination sociale de l'entité : | C3: ='NOTE 1'!C3
A4: Adresse : | B4: ='NOTE 1'!B4 | I4: Sigle usuel : | J4: ='NOTE 1'!I4
A5: N° IFU : | C5: ='NOTE 1'!C5 | F5: Exercice clos le : | G5: ='NOTE 1'!G5 | I5: Durée (en mois) : | J5: ='NOTE 1'!I5
A6: N° de télédéclarant (NES): | C6: ='NOTE 1'!C6
A7: NOTE 7 : CLIENTS
A8: Libellés | E8: Année N | F8: Année N-1 | G8: Variation en % | H8: Créances à un an au plus | I8: Créances à plus d'un an et à deux ans au plus | J8: Créances à plus de deux ans
A9: Clients (hors réserves de propriété et Groupe) | E9: =+BILAN!F31 | F9: 0 | G9: =IF(F9,(E9-F9)/F9,IF(ISBLANK(F9),"",IF(E9,IF( E9 > 0,1,-1),"")))
A10: Clients effets à recevoir (hors réserves de propriété et groupe) | G10: =IF(F10,(E10-F10)/F10,IF(ISBLANK(F10),"",IF(E10,IF( E10 > 0,1,-1),"")))
A11: Clients avec réserves de propriété | G11: =IF(F11,(E11-F11)/F11,IF(ISBLANK(F11),"",IF(E11,IF( E11 > 0,1,-1),"")))
A12: Clients et effets à recevoir Groupe | G12: =IF(F12,(E12-F12)/F12,IF(ISBLANK(F12),"",IF(E12,IF( E12 > 0,1,-1),"")))
A13: Créances sur cession d'immobilisations | G13: =IF(F13,(E13-F13)/F13,IF(ISBLANK(F13),"",IF(E13,IF( E13 > 0,1,-1),"")))
